<?xml version="1.0" ?>
<!-- =================================================================================== -->
<!-- |    This document was autogenerated by xacro from robot.xacro                    | -->
<!-- |    EDITING THIS FILE BY HAND IS NOT RECOMMENDED                                 | -->
<!-- =================================================================================== -->
<robot name="go1">

<link name="base">
  <visual>
    <origin xyz="-0.3 -0.07 -0.040" rpy="0 0 0"/>
    <geometry>
      <box size="0.7 0.25 0.02"/>
    </geometry>
    <material name="orange"/>
  </visual>
  <collision>
    <origin xyz="-0.3 -0.07 -0.040" rpy="0 0 0"/>
    <geometry>
      <box size="0.7 0.25 0.02"/>
    </geometry>
  </collision>
  <inertial>
    <mass value="1.0"/>
    <origin xyz="-0.3 -0.07 -0.040" rpy="0 0 0"/>
    <inertia ixx="0.01" ixy="0" ixz="0" iyy="0.01" iyz="0" izz="0.01"/>
  </inertial>
</link>



<!-- front truck -->
<link name="front_truck">
  <visual>
    <origin xyz="-0 0 -0.07" rpy="0 0 1.57"/>
    <geometry>
      <box size="0.1 0.05 0.05"/>
    </geometry>
    <material name="grey"/>
  </visual>
  <inertial>
    <mass value="0.5"/> 
    <origin xyz="-0 0 -0.07" rpy="0 0 0"/>
  </inertial>
</link>

<!-- rear truck-->
<link name="rear_truck">
  <visual>
    <origin xyz="-0 0 -0.07" rpy="0 0 1.57"/>
    <geometry>
      <box size="0.1 0.05 0.05"/>
    </geometry>
    <material name="grey"/>
  </visual>
  <inertial>
    <mass value="0.5"/> 
    <origin xyz="-0 0 -0.07" rpy="0 0 0"/>
  </inertial>
</link>


<!-- front truck -->
<joint name="front_truck_roll_joint" type="revolute">
  <parent link="base"/>
  <child link="front_truck"/>
  <origin xyz="-0.09 -0.07 -0.05" rpy="0 0 0"/>
  <axis xyz="1 0 0"/>
  <limit lower="-0.2" upper="0.2" effort="10" velocity="10"/> 
</joint>

<!-- rear truck -->
<joint name="rear_truck_roll_joint" type="revolute">
  <parent link="base"/>
  <child link="rear_truck"/>
  <origin xyz="-0.49 -0.07 -0.05" rpy="0 0 0"/>
  <axis xyz="1 0 0"/>
  <limit lower="-0.2" upper="0.2" effort="10" velocity="10"/>
</joint>

<!-- front left wheel -->
<link name="front_left_wheel">
  <visual>
    <origin xyz="0 0.1 0" rpy="1.57 0 0"/>
    <geometry>
      <cylinder length="0.02" radius="0.03"/>
    </geometry>
    <material name="orange"/>
  </visual>
  <collision>
    <origin xyz="0 0.1 0" rpy="1.57 0 0"/>
    <geometry>
      <cylinder length="0.02" radius="0.03"/>
    </geometry>
  </collision>
  <inertial>
    <mass value="0.2"/> 
    <origin xyz="0 0.1 0" rpy="0 0 0"/>
  </inertial>
</link>

<!-- front right wheel -->
<link name="front_right_wheel">
  <visual>
    <origin xyz="0 -0.1 0" rpy="1.57 0 0"/>
    <geometry>
      <cylinder length="0.02" radius="0.03"/>
    </geometry>
    <material name="orange"/>
  </visual>
  <collision>
    <origin xyz="0 -0.1 0" rpy="1.57 0 0"/>
    <geometry>
      <cylinder length="0.02" radius="0.03"/>
    </geometry>
  </collision>
  <inertial>
    <mass value="0.2"/> 
    <origin xyz="0 -0.1 0" rpy="0 0 0"/>
  </inertial>
</link>

<!-- rear left wheel -->
<link name="rear_left_wheel">
  <visual>
    <origin xyz="0 0.1 0" rpy="1.57 0 0"/>
    <geometry>
      <cylinder length="0.02" radius="0.03"/>
    </geometry>
    <material name="orange"/>
  </visual>
  <collision>
    <origin xyz="0 0.1 0" rpy="1.57 0 0"/>
    <geometry>
      <cylinder length="0.02" radius="0.03"/>
    </geometry>
  </collision>
  <inertial>
    <mass value="0.2"/> 
    <origin xyz="0 0.1 0" rpy="0 0 0"/>
  </inertial>
</link>

<!-- rear right wheel -->
<link name="rear_right_wheel">
  <visual>
    <origin xyz="0 -0.1 0" rpy="1.57 0 0"/>
    <geometry>
      <cylinder length="0.02" radius="0.03"/>
    </geometry>
    <material name="orange"/>
  </visual>
  <collision>
    <origin xyz="0 -0.1 0" rpy="1.57 0 0"/>
    <geometry>
      <cylinder length="0.02" radius="0.03"/>
    </geometry>
  </collision>
  <inertial>
    <mass value="0.2"/> 
    <origin xyz="0 -0.1 0" rpy="0 0 0"/>
  </inertial>
</link>


<!-- front left wheel joint-->
<joint name="front_left_wheel_joint" type="continuous">
  <parent link="front_truck"/>
  <child link="front_left_wheel"/>
  <origin xyz="0 0.0 -0.1" rpy="0 0 0"/>
  <axis xyz="0 1 0"/>
  <limit  effort="10" velocity="10"/>
</joint>

<!-- front right wheel joint-->
<joint name="front_right_wheel_joint" type="continuous">
  <parent link="front_truck"/>
  <child link="front_right_wheel"/>
  <origin xyz="0 0.0 -0.1" rpy="0 0 0"/>
  <axis xyz="0 1 0"/>
  <limit  effort="10" velocity="10"/>
</joint>

<!-- rear left wheel joint-->
<joint name="rear_left_wheel_joint" type="continuous">
  <parent link="rear_truck"/>
  <child link="rear_left_wheel"/>
  <origin xyz="0 0.0 -0.1" rpy="0 0 0"/>
  <axis xyz="0 1 0"/>
  <limit  effort="10" velocity="10"/>
</joint>

<!-- rear right wheel joint-->
<joint name="rear_right_wheel_joint" type="continuous">
  <parent link="rear_truck"/>
  <child link="rear_right_wheel"/>
  <origin xyz="0 0.0 -0.1" rpy="0 0 0"/>
  <axis xyz="0 1 0"/>
  <limit  effort="10" velocity="10"/>
</joint>


</robot>

